[2022-10-06 04:58:14,970] {taskinstance.py:1159} INFO - Dependencies all met for <TaskInstance: spark_job_dag.is_repo_exists scheduled__2022-10-05T04:58:12.248574+00:00 [queued]>
[2022-10-06 04:58:14,980] {taskinstance.py:1159} INFO - Dependencies all met for <TaskInstance: spark_job_dag.is_repo_exists scheduled__2022-10-05T04:58:12.248574+00:00 [queued]>
[2022-10-06 04:58:14,981] {taskinstance.py:1356} INFO - 
--------------------------------------------------------------------------------
[2022-10-06 04:58:14,981] {taskinstance.py:1357} INFO - Starting attempt 1 of 2
[2022-10-06 04:58:14,982] {taskinstance.py:1358} INFO - 
--------------------------------------------------------------------------------
[2022-10-06 04:58:14,999] {taskinstance.py:1377} INFO - Executing <Task(BranchPythonOperator): is_repo_exists> on 2022-10-05 04:58:12.248574+00:00
[2022-10-06 04:58:15,006] {standard_task_runner.py:52} INFO - Started process 14522 to run task
[2022-10-06 04:58:15,012] {standard_task_runner.py:79} INFO - Running: ['***', 'tasks', 'run', 'spark_job_dag', 'is_repo_exists', 'scheduled__2022-10-05T04:58:12.248574+00:00', '--job-id', '31', '--raw', '--subdir', 'DAGS_FOLDER/spark_job_dag.py', '--cfg-path', '/tmp/tmpo7oa_prt', '--error-file', '/tmp/tmpkgvrfjbx']
[2022-10-06 04:58:15,014] {standard_task_runner.py:80} INFO - Job 31: Subtask is_repo_exists
[2022-10-06 04:58:15,108] {task_command.py:369} INFO - Running <TaskInstance: spark_job_dag.is_repo_exists scheduled__2022-10-05T04:58:12.248574+00:00 [running]> on host 4e0a50bd41f3
[2022-10-06 04:58:15,196] {taskinstance.py:1571} INFO - Exporting the following env vars:
AIRFLOW_CTX_DAG_OWNER=***
AIRFLOW_CTX_DAG_ID=spark_job_dag
AIRFLOW_CTX_TASK_ID=is_repo_exists
AIRFLOW_CTX_EXECUTION_DATE=2022-10-05T04:58:12.248574+00:00
AIRFLOW_CTX_TRY_NUMBER=1
AIRFLOW_CTX_DAG_RUN_ID=scheduled__2022-10-05T04:58:12.248574+00:00
[2022-10-06 04:58:15,199] {python.py:173} INFO - Done. Returned value was: dummy
[2022-10-06 04:58:15,212] {taskinstance.py:1889} ERROR - Task failed with exception
Traceback (most recent call last):
  File "/home/airflow/.local/lib/python3.7/site-packages/airflow/operators/python.py", line 221, in execute
    f"Branch callable must return valid task_ids. Invalid tasks found: {invalid_task_ids}"
airflow.exceptions.AirflowException: Branch callable must return valid task_ids. Invalid tasks found: {'dummy'}
[2022-10-06 04:58:15,221] {taskinstance.py:1400} INFO - Marking task as UP_FOR_RETRY. dag_id=spark_job_dag, task_id=is_repo_exists, execution_date=20221005T045812, start_date=20221006T045814, end_date=20221006T045815
[2022-10-06 04:58:15,233] {standard_task_runner.py:97} ERROR - Failed to execute job 31 for task is_repo_exists (Branch callable must return valid task_ids. Invalid tasks found: {'dummy'}; 14522)
[2022-10-06 04:58:15,268] {local_task_job.py:156} INFO - Task exited with return code 1
[2022-10-06 04:58:15,326] {local_task_job.py:273} INFO - 0 downstream tasks scheduled from follow-on schedule check
