[2022-08-10 02:44:35,289] {taskinstance.py:1159} INFO - Dependencies all met for <TaskInstance: trigger_rule_dag.task_2 manual__2022-08-10T02:44:33.492780+00:00 [queued]>
[2022-08-10 02:44:35,297] {taskinstance.py:1159} INFO - Dependencies all met for <TaskInstance: trigger_rule_dag.task_2 manual__2022-08-10T02:44:33.492780+00:00 [queued]>
[2022-08-10 02:44:35,298] {taskinstance.py:1356} INFO - 
--------------------------------------------------------------------------------
[2022-08-10 02:44:35,298] {taskinstance.py:1357} INFO - Starting attempt 1 of 1
[2022-08-10 02:44:35,299] {taskinstance.py:1358} INFO - 
--------------------------------------------------------------------------------
[2022-08-10 02:44:35,312] {taskinstance.py:1377} INFO - Executing <Task(BashOperator): task_2> on 2022-08-10 02:44:33.492780+00:00
[2022-08-10 02:44:35,317] {standard_task_runner.py:52} INFO - Started process 167 to run task
[2022-08-10 02:44:35,321] {standard_task_runner.py:79} INFO - Running: ['***', 'tasks', 'run', 'trigger_rule_dag', 'task_2', 'manual__2022-08-10T02:44:33.492780+00:00', '--job-id', '340', '--raw', '--subdir', 'DAGS_FOLDER/trigger_rule_dag.py', '--cfg-path', '/tmp/tmp0u7p96j9', '--error-file', '/tmp/tmpnn71mezh']
[2022-08-10 02:44:35,323] {standard_task_runner.py:80} INFO - Job 340: Subtask task_2
[2022-08-10 02:44:35,387] {task_command.py:369} INFO - Running <TaskInstance: trigger_rule_dag.task_2 manual__2022-08-10T02:44:33.492780+00:00 [running]> on host 2dd699cc72b2
[2022-08-10 02:44:35,479] {taskinstance.py:1571} INFO - Exporting the following env vars:
AIRFLOW_CTX_DAG_OWNER=***
AIRFLOW_CTX_DAG_ID=trigger_rule_dag
AIRFLOW_CTX_TASK_ID=task_2
AIRFLOW_CTX_EXECUTION_DATE=2022-08-10T02:44:33.492780+00:00
AIRFLOW_CTX_TRY_NUMBER=1
AIRFLOW_CTX_DAG_RUN_ID=manual__2022-08-10T02:44:33.492780+00:00
[2022-08-10 02:44:35,482] {subprocess.py:62} INFO - Tmp dir root location: 
 /tmp
[2022-08-10 02:44:35,482] {subprocess.py:74} INFO - Running command: ['bash', '-c', 'exit 1']
[2022-08-10 02:44:35,511] {subprocess.py:85} INFO - Output:
[2022-08-10 02:44:35,517] {subprocess.py:96} INFO - Command exited with return code 1
[2022-08-10 02:44:35,540] {taskinstance.py:1889} ERROR - Task failed with exception
Traceback (most recent call last):
  File "/home/airflow/.local/lib/python3.7/site-packages/airflow/operators/bash.py", line 195, in execute
    f'Bash command failed. The command returned a non-zero exit code {result.exit_code}.'
airflow.exceptions.AirflowException: Bash command failed. The command returned a non-zero exit code 1.
[2022-08-10 02:44:35,545] {taskinstance.py:1400} INFO - Marking task as FAILED. dag_id=trigger_rule_dag, task_id=task_2, execution_date=20220810T024433, start_date=20220810T024435, end_date=20220810T024435
[2022-08-10 02:44:35,558] {standard_task_runner.py:97} ERROR - Failed to execute job 340 for task task_2 (Bash command failed. The command returned a non-zero exit code 1.; 167)
[2022-08-10 02:44:35,580] {local_task_job.py:156} INFO - Task exited with return code 1
[2022-08-10 02:44:35,623] {local_task_job.py:273} INFO - 1 downstream tasks scheduled from follow-on schedule check
