[2022-10-04 21:21:03,306] {taskinstance.py:1159} INFO - Dependencies all met for <TaskInstance: spark_job_dag.docker_command manual__2022-10-04T21:15:49.741574+00:00 [queued]>
[2022-10-04 21:21:03,316] {taskinstance.py:1159} INFO - Dependencies all met for <TaskInstance: spark_job_dag.docker_command manual__2022-10-04T21:15:49.741574+00:00 [queued]>
[2022-10-04 21:21:03,316] {taskinstance.py:1356} INFO - 
--------------------------------------------------------------------------------
[2022-10-04 21:21:03,317] {taskinstance.py:1357} INFO - Starting attempt 2 of 2
[2022-10-04 21:21:03,318] {taskinstance.py:1358} INFO - 
--------------------------------------------------------------------------------
[2022-10-04 21:21:03,338] {taskinstance.py:1377} INFO - Executing <Task(DockerOperator): docker_command> on 2022-10-04 21:15:49.741574+00:00
[2022-10-04 21:21:03,345] {standard_task_runner.py:52} INFO - Started process 118 to run task
[2022-10-04 21:21:03,348] {standard_task_runner.py:79} INFO - Running: ['***', 'tasks', 'run', 'spark_job_dag', 'docker_command', 'manual__2022-10-04T21:15:49.741574+00:00', '--job-id', '18', '--raw', '--subdir', 'DAGS_FOLDER/spark_job_dag.py', '--cfg-path', '/tmp/tmp5leksaqg', '--error-file', '/tmp/tmpo8lipf2a']
[2022-10-04 21:21:03,350] {standard_task_runner.py:80} INFO - Job 18: Subtask docker_command
[2022-10-04 21:21:03,415] {task_command.py:369} INFO - Running <TaskInstance: spark_job_dag.docker_command manual__2022-10-04T21:15:49.741574+00:00 [running]> on host a5cbfeb8bf09
[2022-10-04 21:21:03,531] {taskinstance.py:1571} INFO - Exporting the following env vars:
AIRFLOW_CTX_DAG_OWNER=***
AIRFLOW_CTX_DAG_ID=spark_job_dag
AIRFLOW_CTX_TASK_ID=docker_command
AIRFLOW_CTX_EXECUTION_DATE=2022-10-04T21:15:49.741574+00:00
AIRFLOW_CTX_TRY_NUMBER=2
AIRFLOW_CTX_DAG_RUN_ID=manual__2022-10-04T21:15:49.741574+00:00
[2022-10-04 21:21:03,551] {taskinstance.py:1889} ERROR - Task failed with exception
Traceback (most recent call last):
  File "/home/airflow/.local/lib/python3.7/site-packages/urllib3/connectionpool.py", line 710, in urlopen
    chunked=chunked,
  File "/home/airflow/.local/lib/python3.7/site-packages/urllib3/connectionpool.py", line 398, in _make_request
    conn.request(method, url, **httplib_request_kw)
  File "/usr/local/lib/python3.7/http/client.py", line 1281, in request
    self._send_request(method, url, body, headers, encode_chunked)
  File "/usr/local/lib/python3.7/http/client.py", line 1327, in _send_request
    self.endheaders(body, encode_chunked=encode_chunked)
  File "/usr/local/lib/python3.7/http/client.py", line 1276, in endheaders
    self._send_output(message_body, encode_chunked=encode_chunked)
  File "/usr/local/lib/python3.7/http/client.py", line 1036, in _send_output
    self.send(msg)
  File "/usr/local/lib/python3.7/http/client.py", line 976, in send
    self.connect()
  File "/home/airflow/.local/lib/python3.7/site-packages/docker/transport/unixconn.py", line 30, in connect
    sock.connect(self.unix_socket)
ConnectionRefusedError: [Errno 111] Connection refused

During handling of the above exception, another exception occurred:

Traceback (most recent call last):
  File "/home/airflow/.local/lib/python3.7/site-packages/requests/adapters.py", line 450, in send
    timeout=timeout
  File "/home/airflow/.local/lib/python3.7/site-packages/urllib3/connectionpool.py", line 786, in urlopen
    method, url, error=e, _pool=self, _stacktrace=sys.exc_info()[2]
  File "/home/airflow/.local/lib/python3.7/site-packages/urllib3/util/retry.py", line 550, in increment
    raise six.reraise(type(error), error, _stacktrace)
  File "/home/airflow/.local/lib/python3.7/site-packages/urllib3/packages/six.py", line 769, in reraise
    raise value.with_traceback(tb)
  File "/home/airflow/.local/lib/python3.7/site-packages/urllib3/connectionpool.py", line 710, in urlopen
    chunked=chunked,
  File "/home/airflow/.local/lib/python3.7/site-packages/urllib3/connectionpool.py", line 398, in _make_request
    conn.request(method, url, **httplib_request_kw)
  File "/usr/local/lib/python3.7/http/client.py", line 1281, in request
    self._send_request(method, url, body, headers, encode_chunked)
  File "/usr/local/lib/python3.7/http/client.py", line 1327, in _send_request
    self.endheaders(body, encode_chunked=encode_chunked)
  File "/usr/local/lib/python3.7/http/client.py", line 1276, in endheaders
    self._send_output(message_body, encode_chunked=encode_chunked)
  File "/usr/local/lib/python3.7/http/client.py", line 1036, in _send_output
    self.send(msg)
  File "/usr/local/lib/python3.7/http/client.py", line 976, in send
    self.connect()
  File "/home/airflow/.local/lib/python3.7/site-packages/docker/transport/unixconn.py", line 30, in connect
    sock.connect(self.unix_socket)
urllib3.exceptions.ProtocolError: ('Connection aborted.', ConnectionRefusedError(111, 'Connection refused'))

During handling of the above exception, another exception occurred:

Traceback (most recent call last):
  File "/home/airflow/.local/lib/python3.7/site-packages/airflow/providers/docker/operators/docker.py", line 370, in execute
    if self.force_pull or not self.cli.images(name=self.image):
  File "/home/airflow/.local/lib/python3.7/site-packages/docker/api/image.py", line 96, in images
    res = self._result(self._get(self._url("/images/json"), params=params),
  File "/home/airflow/.local/lib/python3.7/site-packages/docker/utils/decorators.py", line 46, in inner
    return f(self, *args, **kwargs)
  File "/home/airflow/.local/lib/python3.7/site-packages/docker/api/client.py", line 237, in _get
    return self.get(url, **self._set_request_timeout(kwargs))
  File "/home/airflow/.local/lib/python3.7/site-packages/requests/sessions.py", line 542, in get
    return self.request('GET', url, **kwargs)
  File "/home/airflow/.local/lib/python3.7/site-packages/requests/sessions.py", line 529, in request
    resp = self.send(prep, **send_kwargs)
  File "/home/airflow/.local/lib/python3.7/site-packages/requests/sessions.py", line 645, in send
    r = adapter.send(request, **kwargs)
  File "/home/airflow/.local/lib/python3.7/site-packages/requests/adapters.py", line 501, in send
    raise ConnectionError(err, request=request)
requests.exceptions.ConnectionError: ('Connection aborted.', ConnectionRefusedError(111, 'Connection refused'))
[2022-10-04 21:21:03,570] {taskinstance.py:1400} INFO - Marking task as FAILED. dag_id=spark_job_dag, task_id=docker_command, execution_date=20221004T211549, start_date=20221004T212103, end_date=20221004T212103
[2022-10-04 21:21:03,587] {standard_task_runner.py:97} ERROR - Failed to execute job 18 for task docker_command (('Connection aborted.', ConnectionRefusedError(111, 'Connection refused')); 118)
[2022-10-04 21:21:03,605] {local_task_job.py:156} INFO - Task exited with return code 1
[2022-10-04 21:21:03,639] {local_task_job.py:273} INFO - 0 downstream tasks scheduled from follow-on schedule check
