[2022-08-18 15:59:37,816] {taskinstance.py:1159} INFO - Dependencies all met for <TaskInstance: docker_dag.docker_command scheduled__2022-08-18T10:05:00+00:00 [queued]>
[2022-08-18 15:59:37,831] {taskinstance.py:1159} INFO - Dependencies all met for <TaskInstance: docker_dag.docker_command scheduled__2022-08-18T10:05:00+00:00 [queued]>
[2022-08-18 15:59:37,835] {taskinstance.py:1356} INFO - 
--------------------------------------------------------------------------------
[2022-08-18 15:59:37,836] {taskinstance.py:1357} INFO - Starting attempt 2 of 2
[2022-08-18 15:59:37,836] {taskinstance.py:1358} INFO - 
--------------------------------------------------------------------------------
[2022-08-18 15:59:37,911] {taskinstance.py:1377} INFO - Executing <Task(DockerOperator): docker_command> on 2022-08-18 10:05:00+00:00
[2022-08-18 15:59:37,918] {standard_task_runner.py:52} INFO - Started process 13877 to run task
[2022-08-18 15:59:37,924] {standard_task_runner.py:79} INFO - Running: ['***', 'tasks', 'run', 'docker_dag', 'docker_command', 'scheduled__2022-08-18T10:05:00+00:00', '--job-id', '538', '--raw', '--subdir', 'DAGS_FOLDER/docker_dag.py', '--cfg-path', '/tmp/tmp7m57d6v4', '--error-file', '/tmp/tmpzgissvhn']
[2022-08-18 15:59:37,926] {standard_task_runner.py:80} INFO - Job 538: Subtask docker_command
[2022-08-18 15:59:38,048] {task_command.py:369} INFO - Running <TaskInstance: docker_dag.docker_command scheduled__2022-08-18T10:05:00+00:00 [running]> on host e8f82214d52e
[2022-08-18 15:59:38,174] {taskinstance.py:1571} INFO - Exporting the following env vars:
AIRFLOW_CTX_DAG_OWNER=***
AIRFLOW_CTX_DAG_ID=docker_dag
AIRFLOW_CTX_TASK_ID=docker_command
AIRFLOW_CTX_EXECUTION_DATE=2022-08-18T10:05:00+00:00
AIRFLOW_CTX_TRY_NUMBER=2
AIRFLOW_CTX_DAG_RUN_ID=scheduled__2022-08-18T10:05:00+00:00
[2022-08-18 15:59:38,217] {taskinstance.py:1889} ERROR - Task failed with exception
Traceback (most recent call last):
  File "/home/airflow/.local/lib/python3.7/site-packages/airflow/providers/docker/operators/docker.py", line 364, in execute
    self.cli = self._get_cli()
  File "/home/airflow/.local/lib/python3.7/site-packages/airflow/providers/docker/operators/docker.py", line 395, in _get_cli
    base_url=self.docker_url, version=self.api_version, tls=tls_config, timeout=self.timeout
  File "/home/airflow/.local/lib/python3.7/site-packages/docker/api/client.py", line 137, in __init__
    base_url, IS_WINDOWS_PLATFORM, tls=bool(tls)
  File "/home/airflow/.local/lib/python3.7/site-packages/docker/utils/utils.py", line 274, in parse_host
    ' {}'.format(addr)
docker.errors.DockerException: Invalid bind address format: port is required: docker_url='tcp://127.0.0.1:2375
[2022-08-18 15:59:38,233] {taskinstance.py:1400} INFO - Marking task as FAILED. dag_id=docker_dag, task_id=docker_command, execution_date=20220818T100500, start_date=20220818T155937, end_date=20220818T155938
[2022-08-18 15:59:38,252] {standard_task_runner.py:97} ERROR - Failed to execute job 538 for task docker_command (Invalid bind address format: port is required: docker_url='tcp://127.0.0.1:2375; 13877)
[2022-08-18 15:59:38,302] {local_task_job.py:156} INFO - Task exited with return code 1
[2022-08-18 15:59:38,393] {local_task_job.py:273} INFO - 0 downstream tasks scheduled from follow-on schedule check
