[2022-10-27 02:57:34,955] {taskinstance.py:1159} INFO - Dependencies all met for <TaskInstance: spark_job_dag.docker_command manual__2022-10-27T02:57:26.771756+00:00 [queued]>
[2022-10-27 02:57:34,964] {taskinstance.py:1159} INFO - Dependencies all met for <TaskInstance: spark_job_dag.docker_command manual__2022-10-27T02:57:26.771756+00:00 [queued]>
[2022-10-27 02:57:34,965] {taskinstance.py:1356} INFO - 
--------------------------------------------------------------------------------
[2022-10-27 02:57:34,965] {taskinstance.py:1357} INFO - Starting attempt 1 of 2
[2022-10-27 02:57:34,966] {taskinstance.py:1358} INFO - 
--------------------------------------------------------------------------------
[2022-10-27 02:57:34,978] {taskinstance.py:1377} INFO - Executing <Task(DockerOperator): docker_command> on 2022-10-27 02:57:26.771756+00:00
[2022-10-27 02:57:34,984] {standard_task_runner.py:52} INFO - Started process 184 to run task
[2022-10-27 02:57:34,987] {standard_task_runner.py:79} INFO - Running: ['***', 'tasks', 'run', 'spark_job_dag', 'docker_command', 'manual__2022-10-27T02:57:26.771756+00:00', '--job-id', '76', '--raw', '--subdir', 'DAGS_FOLDER/spark_job_dag.py', '--cfg-path', '/tmp/tmp7xswd16b', '--error-file', '/tmp/tmplnpzdqrl']
[2022-10-27 02:57:34,989] {standard_task_runner.py:80} INFO - Job 76: Subtask docker_command
[2022-10-27 02:57:35,046] {task_command.py:369} INFO - Running <TaskInstance: spark_job_dag.docker_command manual__2022-10-27T02:57:26.771756+00:00 [running]> on host 7a39bdd9f452
[2022-10-27 02:57:35,121] {taskinstance.py:1571} INFO - Exporting the following env vars:
AIRFLOW_CTX_DAG_OWNER=***
AIRFLOW_CTX_DAG_ID=spark_job_dag
AIRFLOW_CTX_TASK_ID=docker_command
AIRFLOW_CTX_EXECUTION_DATE=2022-10-27T02:57:26.771756+00:00
AIRFLOW_CTX_TRY_NUMBER=1
AIRFLOW_CTX_DAG_RUN_ID=manual__2022-10-27T02:57:26.771756+00:00
[2022-10-27 02:57:35,155] {docker.py:247} INFO - Starting docker container from image bde2020/spark-master:latest
[2022-10-27 02:57:35,190] {taskinstance.py:1889} ERROR - Task failed with exception
Traceback (most recent call last):
  File "/home/airflow/.local/lib/python3.7/site-packages/docker/api/client.py", line 268, in _raise_for_status
    response.raise_for_status()
  File "/home/airflow/.local/lib/python3.7/site-packages/requests/models.py", line 960, in raise_for_status
    raise HTTPError(http_error_msg, response=self)
requests.exceptions.HTTPError: 400 Client Error: Bad Request for url: http://docker-socket-proxy:2375/v1.37/containers/create

During handling of the above exception, another exception occurred:

Traceback (most recent call last):
  File "/home/airflow/.local/lib/python3.7/site-packages/airflow/providers/docker/operators/docker.py", line 387, in execute
    return self._run_image()
  File "/home/airflow/.local/lib/python3.7/site-packages/airflow/providers/docker/operators/docker.py", line 254, in _run_image
    return self._run_image_with_mounts(self.mounts + [tmp_mount], add_tmp_variable=True)
  File "/home/airflow/.local/lib/python3.7/site-packages/airflow/providers/docker/operators/docker.py", line 298, in _run_image_with_mounts
    tty=self.tty,
  File "/home/airflow/.local/lib/python3.7/site-packages/docker/api/container.py", line 428, in create_container
    return self.create_container_from_config(config, name)
  File "/home/airflow/.local/lib/python3.7/site-packages/docker/api/container.py", line 439, in create_container_from_config
    return self._result(res, True)
  File "/home/airflow/.local/lib/python3.7/site-packages/docker/api/client.py", line 274, in _result
    self._raise_for_status(response)
  File "/home/airflow/.local/lib/python3.7/site-packages/docker/api/client.py", line 270, in _raise_for_status
    raise create_api_error_from_http_exception(e)
  File "/home/airflow/.local/lib/python3.7/site-packages/docker/errors.py", line 31, in create_api_error_from_http_exception
    raise cls(e, response=response, explanation=explanation)
docker.errors.APIError: 400 Client Error for http://docker-socket-proxy:2375/v1.37/containers/create: Bad Request ("invalid mount config for type "bind": bind source path does not exist: /home/airflow/simple-app")
[2022-10-27 02:57:35,205] {taskinstance.py:1400} INFO - Marking task as UP_FOR_RETRY. dag_id=spark_job_dag, task_id=docker_command, execution_date=20221027T025726, start_date=20221027T025734, end_date=20221027T025735
[2022-10-27 02:57:35,216] {standard_task_runner.py:97} ERROR - Failed to execute job 76 for task docker_command (400 Client Error for http://docker-socket-proxy:2375/v1.37/containers/create: Bad Request ("invalid mount config for type "bind": bind source path does not exist: /home/airflow/simple-app"); 184)
[2022-10-27 02:57:35,241] {local_task_job.py:156} INFO - Task exited with return code 1
[2022-10-27 02:57:35,284] {local_task_job.py:273} INFO - 0 downstream tasks scheduled from follow-on schedule check
