[2022-08-18 23:19:48,818] {taskinstance.py:1159} INFO - Dependencies all met for <TaskInstance: docker_dag.docker_command manual__2022-08-18T23:14:36.713840+00:00 [queued]>
[2022-08-18 23:19:48,830] {taskinstance.py:1159} INFO - Dependencies all met for <TaskInstance: docker_dag.docker_command manual__2022-08-18T23:14:36.713840+00:00 [queued]>
[2022-08-18 23:19:48,831] {taskinstance.py:1356} INFO - 
--------------------------------------------------------------------------------
[2022-08-18 23:19:48,832] {taskinstance.py:1357} INFO - Starting attempt 2 of 2
[2022-08-18 23:19:48,833] {taskinstance.py:1358} INFO - 
--------------------------------------------------------------------------------
[2022-08-18 23:19:48,851] {taskinstance.py:1377} INFO - Executing <Task(DockerOperator): docker_command> on 2022-08-18 23:14:36.713840+00:00
[2022-08-18 23:19:48,859] {standard_task_runner.py:52} INFO - Started process 414 to run task
[2022-08-18 23:19:48,876] {standard_task_runner.py:79} INFO - Running: ['***', 'tasks', 'run', 'docker_dag', 'docker_command', 'manual__2022-08-18T23:14:36.713840+00:00', '--job-id', '572', '--raw', '--subdir', 'DAGS_FOLDER/docker_dag.py', '--cfg-path', '/tmp/tmp4jdrk8ix', '--error-file', '/tmp/tmp3lu8tglx']
[2022-08-18 23:19:48,878] {standard_task_runner.py:80} INFO - Job 572: Subtask docker_command
[2022-08-18 23:19:48,962] {task_command.py:369} INFO - Running <TaskInstance: docker_dag.docker_command manual__2022-08-18T23:14:36.713840+00:00 [running]> on host b127da6a566b
[2022-08-18 23:19:49,062] {taskinstance.py:1571} INFO - Exporting the following env vars:
AIRFLOW_CTX_DAG_OWNER=***
AIRFLOW_CTX_DAG_ID=docker_dag
AIRFLOW_CTX_TASK_ID=docker_command
AIRFLOW_CTX_EXECUTION_DATE=2022-08-18T23:14:36.713840+00:00
AIRFLOW_CTX_TRY_NUMBER=2
AIRFLOW_CTX_DAG_RUN_ID=manual__2022-08-18T23:14:36.713840+00:00
[2022-08-18 23:19:49,111] {docker.py:247} INFO - Starting docker container from image bobrik/socat
[2022-08-18 23:19:49,132] {docker.py:258} WARNING - Using remote engine or docker-in-docker and mounting temporary volume from host is not supported. Falling back to `mount_tmp_dir=False` mode. You can set `mount_tmp_dir` parameter to False to disable mounting and remove the warning
[2022-08-18 23:19:50,051] {docker.py:308} INFO - 2022/08/18 23:19:50 socat[1] E unknown device/address "30"
[2022-08-18 23:19:50,229] {taskinstance.py:1889} ERROR - Task failed with exception
Traceback (most recent call last):
  File "/home/airflow/.local/lib/python3.7/site-packages/docker/api/client.py", line 268, in _raise_for_status
    response.raise_for_status()
  File "/home/airflow/.local/lib/python3.7/site-packages/requests/models.py", line 960, in raise_for_status
    raise HTTPError(http_error_msg, response=self)
requests.exceptions.HTTPError: 400 Client Error: Bad Request for url: http://docker-proxy:2375/v1.41/containers/create

During handling of the above exception, another exception occurred:

Traceback (most recent call last):
  File "/home/airflow/.local/lib/python3.7/site-packages/airflow/providers/docker/operators/docker.py", line 254, in _run_image
    return self._run_image_with_mounts(self.mounts + [tmp_mount], add_tmp_variable=True)
  File "/home/airflow/.local/lib/python3.7/site-packages/airflow/providers/docker/operators/docker.py", line 298, in _run_image_with_mounts
    tty=self.tty,
  File "/home/airflow/.local/lib/python3.7/site-packages/docker/api/container.py", line 428, in create_container
    return self.create_container_from_config(config, name)
  File "/home/airflow/.local/lib/python3.7/site-packages/docker/api/container.py", line 439, in create_container_from_config
    return self._result(res, True)
  File "/home/airflow/.local/lib/python3.7/site-packages/docker/api/client.py", line 274, in _result
    self._raise_for_status(response)
  File "/home/airflow/.local/lib/python3.7/site-packages/docker/api/client.py", line 270, in _raise_for_status
    raise create_api_error_from_http_exception(e)
  File "/home/airflow/.local/lib/python3.7/site-packages/docker/errors.py", line 31, in create_api_error_from_http_exception
    raise cls(e, response=response, explanation=explanation)
docker.errors.APIError: 400 Client Error for http://docker-proxy:2375/v1.41/containers/create: Bad Request ("invalid mount config for type "bind": bind source path does not exist: /tmp/airflowtmp8c3jl3pu")

During handling of the above exception, another exception occurred:

Traceback (most recent call last):
  File "/home/airflow/.local/lib/python3.7/site-packages/airflow/providers/docker/operators/docker.py", line 387, in execute
    return self._run_image()
  File "/home/airflow/.local/lib/python3.7/site-packages/airflow/providers/docker/operators/docker.py", line 263, in _run_image
    return self._run_image_with_mounts(self.mounts, add_tmp_variable=False)
  File "/home/airflow/.local/lib/python3.7/site-packages/airflow/providers/docker/operators/docker.py", line 313, in _run_image_with_mounts
    raise AirflowException(f'Docker container failed: {repr(result)} lines {joined_log_lines}')
airflow.exceptions.AirflowException: Docker container failed: {'Error': None, 'StatusCode': 1} lines 2022/08/18 23:19:50 socat[1] E unknown device/address "30"
[2022-08-18 23:19:50,242] {taskinstance.py:1400} INFO - Marking task as FAILED. dag_id=docker_dag, task_id=docker_command, execution_date=20220818T231436, start_date=20220818T231948, end_date=20220818T231950
[2022-08-18 23:19:50,266] {standard_task_runner.py:97} ERROR - Failed to execute job 572 for task docker_command (Docker container failed: {'Error': None, 'StatusCode': 1} lines 2022/08/18 23:19:50 socat[1] E unknown device/address "30"; 414)
[2022-08-18 23:19:50,317] {local_task_job.py:156} INFO - Task exited with return code 1
[2022-08-18 23:19:50,395] {local_task_job.py:273} INFO - 0 downstream tasks scheduled from follow-on schedule check
