[2022-07-28 13:05:09,474] {taskinstance.py:1159} INFO - Dependencies all met for <TaskInstance: trigger_rule_dag.task_2 manual__2022-07-28T13:05:08.586177+00:00 [queued]>
[2022-07-28 13:05:09,483] {taskinstance.py:1159} INFO - Dependencies all met for <TaskInstance: trigger_rule_dag.task_2 manual__2022-07-28T13:05:08.586177+00:00 [queued]>
[2022-07-28 13:05:09,484] {taskinstance.py:1356} INFO - 
--------------------------------------------------------------------------------
[2022-07-28 13:05:09,485] {taskinstance.py:1357} INFO - Starting attempt 1 of 1
[2022-07-28 13:05:09,485] {taskinstance.py:1358} INFO - 
--------------------------------------------------------------------------------
[2022-07-28 13:05:09,498] {taskinstance.py:1377} INFO - Executing <Task(BashOperator): task_2> on 2022-07-28 13:05:08.586177+00:00
[2022-07-28 13:05:09,503] {standard_task_runner.py:52} INFO - Started process 1835 to run task
[2022-07-28 13:05:09,506] {standard_task_runner.py:79} INFO - Running: ['***', 'tasks', 'run', 'trigger_rule_dag', 'task_2', 'manual__2022-07-28T13:05:08.586177+00:00', '--job-id', '231', '--raw', '--subdir', 'DAGS_FOLDER/trigger_rule_dag.py', '--cfg-path', '/tmp/tmp471pm632', '--error-file', '/tmp/tmpuo2oa1_8']
[2022-07-28 13:05:09,507] {standard_task_runner.py:80} INFO - Job 231: Subtask task_2
[2022-07-28 13:05:09,569] {task_command.py:369} INFO - Running <TaskInstance: trigger_rule_dag.task_2 manual__2022-07-28T13:05:08.586177+00:00 [running]> on host 2525a2c6e2b8
[2022-07-28 13:05:09,637] {taskinstance.py:1571} INFO - Exporting the following env vars:
AIRFLOW_CTX_DAG_OWNER=***
AIRFLOW_CTX_DAG_ID=trigger_rule_dag
AIRFLOW_CTX_TASK_ID=task_2
AIRFLOW_CTX_EXECUTION_DATE=2022-07-28T13:05:08.586177+00:00
AIRFLOW_CTX_TRY_NUMBER=1
AIRFLOW_CTX_DAG_RUN_ID=manual__2022-07-28T13:05:08.586177+00:00
[2022-07-28 13:05:09,639] {subprocess.py:62} INFO - Tmp dir root location: 
 /tmp
[2022-07-28 13:05:09,659] {subprocess.py:74} INFO - Running command: ['bash', '-c', 'exit 1']
[2022-07-28 13:05:09,671] {subprocess.py:85} INFO - Output:
[2022-07-28 13:05:09,673] {subprocess.py:96} INFO - Command exited with return code 1
[2022-07-28 13:05:09,689] {taskinstance.py:1889} ERROR - Task failed with exception
Traceback (most recent call last):
  File "/home/airflow/.local/lib/python3.7/site-packages/airflow/operators/bash.py", line 195, in execute
    f'Bash command failed. The command returned a non-zero exit code {result.exit_code}.'
airflow.exceptions.AirflowException: Bash command failed. The command returned a non-zero exit code 1.
[2022-07-28 13:05:09,693] {taskinstance.py:1400} INFO - Marking task as FAILED. dag_id=trigger_rule_dag, task_id=task_2, execution_date=20220728T130508, start_date=20220728T130509, end_date=20220728T130509
[2022-07-28 13:05:09,704] {standard_task_runner.py:97} ERROR - Failed to execute job 231 for task task_2 (Bash command failed. The command returned a non-zero exit code 1.; 1835)
[2022-07-28 13:05:09,719] {local_task_job.py:156} INFO - Task exited with return code 1
[2022-07-28 13:05:09,753] {local_task_job.py:273} INFO - 1 downstream tasks scheduled from follow-on schedule check
