[2022-08-18 04:52:05,401] {taskinstance.py:1159} INFO - Dependencies all met for <TaskInstance: docker_dag.docker_command manual__2022-08-18T04:52:03.445817+00:00 [queued]>
[2022-08-18 04:52:05,410] {taskinstance.py:1159} INFO - Dependencies all met for <TaskInstance: docker_dag.docker_command manual__2022-08-18T04:52:03.445817+00:00 [queued]>
[2022-08-18 04:52:05,411] {taskinstance.py:1356} INFO - 
--------------------------------------------------------------------------------
[2022-08-18 04:52:05,411] {taskinstance.py:1357} INFO - Starting attempt 1 of 2
[2022-08-18 04:52:05,412] {taskinstance.py:1358} INFO - 
--------------------------------------------------------------------------------
[2022-08-18 04:52:05,425] {taskinstance.py:1377} INFO - Executing <Task(DockerOperator): docker_command> on 2022-08-18 04:52:03.445817+00:00
[2022-08-18 04:52:05,431] {standard_task_runner.py:52} INFO - Started process 13186 to run task
[2022-08-18 04:52:05,435] {standard_task_runner.py:79} INFO - Running: ['***', 'tasks', 'run', 'docker_dag', 'docker_command', 'manual__2022-08-18T04:52:03.445817+00:00', '--job-id', '512', '--raw', '--subdir', 'DAGS_FOLDER/docker_dag.py', '--cfg-path', '/tmp/tmpk0yv0ky9', '--error-file', '/tmp/tmpc_op2pb6']
[2022-08-18 04:52:05,436] {standard_task_runner.py:80} INFO - Job 512: Subtask docker_command
[2022-08-18 04:52:05,500] {task_command.py:369} INFO - Running <TaskInstance: docker_dag.docker_command manual__2022-08-18T04:52:03.445817+00:00 [running]> on host e8f82214d52e
[2022-08-18 04:52:05,580] {taskinstance.py:1571} INFO - Exporting the following env vars:
AIRFLOW_CTX_DAG_OWNER=***
AIRFLOW_CTX_DAG_ID=docker_dag
AIRFLOW_CTX_TASK_ID=docker_command
AIRFLOW_CTX_EXECUTION_DATE=2022-08-18T04:52:03.445817+00:00
AIRFLOW_CTX_TRY_NUMBER=1
AIRFLOW_CTX_DAG_RUN_ID=manual__2022-08-18T04:52:03.445817+00:00
[2022-08-18 04:52:05,583] {taskinstance.py:1889} ERROR - Task failed with exception
Traceback (most recent call last):
  File "/home/airflow/.local/lib/python3.7/site-packages/airflow/providers/docker/operators/docker.py", line 364, in execute
    self.cli = self._get_cli()
  File "/home/airflow/.local/lib/python3.7/site-packages/airflow/providers/docker/operators/docker.py", line 395, in _get_cli
    base_url=self.docker_url, version=self.api_version, tls=tls_config, timeout=self.timeout
  File "/home/airflow/.local/lib/python3.7/site-packages/docker/api/client.py", line 137, in __init__
    base_url, IS_WINDOWS_PLATFORM, tls=bool(tls)
  File "/home/airflow/.local/lib/python3.7/site-packages/docker/utils/utils.py", line 274, in parse_host
    ' {}'.format(addr)
docker.errors.DockerException: Invalid bind address format: port is required: docker_url='tcp://docker-proxy:2375
[2022-08-18 04:52:05,593] {taskinstance.py:1400} INFO - Marking task as UP_FOR_RETRY. dag_id=docker_dag, task_id=docker_command, execution_date=20220818T045203, start_date=20220818T045205, end_date=20220818T045205
[2022-08-18 04:52:05,604] {standard_task_runner.py:97} ERROR - Failed to execute job 512 for task docker_command (Invalid bind address format: port is required: docker_url='tcp://docker-proxy:2375; 13186)
[2022-08-18 04:52:05,648] {local_task_job.py:156} INFO - Task exited with return code 1
[2022-08-18 04:52:05,689] {local_task_job.py:273} INFO - 0 downstream tasks scheduled from follow-on schedule check
