[2022-08-12 03:53:38,498] {taskinstance.py:1159} INFO - Dependencies all met for <TaskInstance: elasticsearch_dag.connections_to_es manual__2022-08-12T03:53:35.709163+00:00 [queued]>
[2022-08-12 03:53:38,507] {taskinstance.py:1159} INFO - Dependencies all met for <TaskInstance: elasticsearch_dag.connections_to_es manual__2022-08-12T03:53:35.709163+00:00 [queued]>
[2022-08-12 03:53:38,508] {taskinstance.py:1356} INFO - 
--------------------------------------------------------------------------------
[2022-08-12 03:53:38,508] {taskinstance.py:1357} INFO - Starting attempt 1 of 1
[2022-08-12 03:53:38,509] {taskinstance.py:1358} INFO - 
--------------------------------------------------------------------------------
[2022-08-12 03:53:38,522] {taskinstance.py:1377} INFO - Executing <Task(PostgresToElasticOperator): connections_to_es> on 2022-08-12 03:53:35.709163+00:00
[2022-08-12 03:53:38,528] {standard_task_runner.py:52} INFO - Started process 2677 to run task
[2022-08-12 03:53:38,532] {standard_task_runner.py:79} INFO - Running: ['***', 'tasks', 'run', 'elasticsearch_dag', 'connections_to_es', 'manual__2022-08-12T03:53:35.709163+00:00', '--job-id', '391', '--raw', '--subdir', 'DAGS_FOLDER/elastic_dag.py', '--cfg-path', '/tmp/tmplax8xzkj', '--error-file', '/tmp/tmpnsh_rwd9']
[2022-08-12 03:53:38,533] {standard_task_runner.py:80} INFO - Job 391: Subtask connections_to_es
[2022-08-12 03:53:38,593] {task_command.py:369} INFO - Running <TaskInstance: elasticsearch_dag.connections_to_es manual__2022-08-12T03:53:35.709163+00:00 [running]> on host a1c9528fe5e1
[2022-08-12 03:53:38,663] {taskinstance.py:1571} INFO - Exporting the following env vars:
AIRFLOW_CTX_DAG_OWNER=***
AIRFLOW_CTX_DAG_ID=elasticsearch_dag
AIRFLOW_CTX_TASK_ID=connections_to_es
AIRFLOW_CTX_EXECUTION_DATE=2022-08-12T03:53:35.709163+00:00
AIRFLOW_CTX_TRY_NUMBER=1
AIRFLOW_CTX_DAG_RUN_ID=manual__2022-08-12T03:53:35.709163+00:00
[2022-08-12 03:53:38,672] {base.py:68} INFO - Using connection ID 'elasticsearch_default' for task execution.
[2022-08-12 03:53:38,679] {base.py:68} INFO - Using connection ID 'postgres_default' for task execution.
[2022-08-12 03:53:38,691] {base.py:299} WARNING - POST http://es01:9200/connections/external [status:400 request:0.006s]
[2022-08-12 03:53:38,692] {taskinstance.py:1889} ERROR - Task failed with exception
Traceback (most recent call last):
  File "/opt/airflow/dags/operators/postgres_to_elastic.py", line 29, in execute
    es.add_doc(index= self.index, doc_type = 'external' , doc=doc)
  File "/opt/airflow/dags/plugins/elastic_search_plugin/hooks/elastic_hook.py", line 33, in add_doc
    res = self.es.index(index=index, doc_type=doc_type, body=doc)
  File "/home/airflow/.local/lib/python3.7/site-packages/elasticsearch/client/utils.py", line 168, in _wrapped
    return func(*args, params=params, headers=headers, **kwargs)
  File "/home/airflow/.local/lib/python3.7/site-packages/elasticsearch/client/__init__.py", line 411, in index
    body=body,
  File "/home/airflow/.local/lib/python3.7/site-packages/elasticsearch/transport.py", line 415, in perform_request
    raise e
  File "/home/airflow/.local/lib/python3.7/site-packages/elasticsearch/transport.py", line 388, in perform_request
    timeout=timeout,
  File "/home/airflow/.local/lib/python3.7/site-packages/elasticsearch/connection/http_urllib3.py", line 277, in perform_request
    self._raise_error(response.status, raw_data)
  File "/home/airflow/.local/lib/python3.7/site-packages/elasticsearch/connection/base.py", line 331, in _raise_error
    status_code, error_message, additional_info
elasticsearch.exceptions.RequestError: RequestError(400, 'no handler found for uri [/connections/external] and method [POST]', 'no handler found for uri [/connections/external] and method [POST]')
[2022-08-12 03:53:38,707] {taskinstance.py:1400} INFO - Marking task as FAILED. dag_id=elasticsearch_dag, task_id=connections_to_es, execution_date=20220812T035335, start_date=20220812T035338, end_date=20220812T035338
[2022-08-12 03:53:38,717] {standard_task_runner.py:97} ERROR - Failed to execute job 391 for task connections_to_es (RequestError(400, 'no handler found for uri [/connections/external] and method [POST]', 'no handler found for uri [/connections/external] and method [POST]'); 2677)
[2022-08-12 03:53:38,745] {local_task_job.py:156} INFO - Task exited with return code 1
[2022-08-12 03:53:38,780] {local_task_job.py:273} INFO - 0 downstream tasks scheduled from follow-on schedule check
