[2022-08-19 00:15:59,962] {taskinstance.py:1159} INFO - Dependencies all met for <TaskInstance: docker_dag.docker_command manual__2022-08-19T00:15:54.178667+00:00 [queued]>
[2022-08-19 00:16:00,233] {taskinstance.py:1159} INFO - Dependencies all met for <TaskInstance: docker_dag.docker_command manual__2022-08-19T00:15:54.178667+00:00 [queued]>
[2022-08-19 00:16:00,240] {taskinstance.py:1356} INFO - 
--------------------------------------------------------------------------------
[2022-08-19 00:16:00,261] {taskinstance.py:1357} INFO - Starting attempt 1 of 2
[2022-08-19 00:16:00,273] {taskinstance.py:1358} INFO - 
--------------------------------------------------------------------------------
[2022-08-19 00:16:00,405] {taskinstance.py:1377} INFO - Executing <Task(DockerOperator): docker_command> on 2022-08-19 00:15:54.178667+00:00
[2022-08-19 00:16:00,514] {standard_task_runner.py:52} INFO - Started process 501 to run task
[2022-08-19 00:16:00,548] {standard_task_runner.py:79} INFO - Running: ['***', 'tasks', 'run', 'docker_dag', 'docker_command', 'manual__2022-08-19T00:15:54.178667+00:00', '--job-id', '586', '--raw', '--subdir', 'DAGS_FOLDER/docker_dag.py', '--cfg-path', '/tmp/tmp78uv2481', '--error-file', '/tmp/tmpro360sk8']
[2022-08-19 00:16:00,556] {standard_task_runner.py:80} INFO - Job 586: Subtask docker_command
[2022-08-19 00:16:00,914] {task_command.py:369} INFO - Running <TaskInstance: docker_dag.docker_command manual__2022-08-19T00:15:54.178667+00:00 [running]> on host 50aef51b862a
[2022-08-19 00:16:01,295] {taskinstance.py:1571} INFO - Exporting the following env vars:
AIRFLOW_CTX_DAG_OWNER=***
AIRFLOW_CTX_DAG_ID=docker_dag
AIRFLOW_CTX_TASK_ID=docker_command
AIRFLOW_CTX_EXECUTION_DATE=2022-08-19T00:15:54.178667+00:00
AIRFLOW_CTX_TRY_NUMBER=1
AIRFLOW_CTX_DAG_RUN_ID=manual__2022-08-19T00:15:54.178667+00:00
[2022-08-19 00:16:01,428] {docker.py:247} INFO - Starting docker container from image bobrik/socat
[2022-08-19 00:16:01,474] {taskinstance.py:1889} ERROR - Task failed with exception
Traceback (most recent call last):
  File "/home/airflow/.local/lib/python3.7/site-packages/docker/api/client.py", line 268, in _raise_for_status
    response.raise_for_status()
  File "/home/airflow/.local/lib/python3.7/site-packages/requests/models.py", line 960, in raise_for_status
    raise HTTPError(http_error_msg, response=self)
requests.exceptions.HTTPError: 500 Server Error: Internal Server Error for url: http://docker-proxy:2375/v1.41/containers/create

During handling of the above exception, another exception occurred:

Traceback (most recent call last):
  File "/home/airflow/.local/lib/python3.7/site-packages/airflow/providers/docker/operators/docker.py", line 387, in execute
    return self._run_image()
  File "/home/airflow/.local/lib/python3.7/site-packages/airflow/providers/docker/operators/docker.py", line 254, in _run_image
    return self._run_image_with_mounts(self.mounts + [tmp_mount], add_tmp_variable=True)
  File "/home/airflow/.local/lib/python3.7/site-packages/airflow/providers/docker/operators/docker.py", line 298, in _run_image_with_mounts
    tty=self.tty,
  File "/home/airflow/.local/lib/python3.7/site-packages/docker/api/container.py", line 428, in create_container
    return self.create_container_from_config(config, name)
  File "/home/airflow/.local/lib/python3.7/site-packages/docker/api/container.py", line 439, in create_container_from_config
    return self._result(res, True)
  File "/home/airflow/.local/lib/python3.7/site-packages/docker/api/client.py", line 274, in _result
    self._raise_for_status(response)
  File "/home/airflow/.local/lib/python3.7/site-packages/docker/api/client.py", line 270, in _raise_for_status
    raise create_api_error_from_http_exception(e)
  File "/home/airflow/.local/lib/python3.7/site-packages/docker/errors.py", line 31, in create_api_error_from_http_exception
    raise cls(e, response=response, explanation=explanation)
docker.errors.APIError: 500 Server Error for http://docker-proxy:2375/v1.41/containers/create: Internal Server Error ("json: cannot unmarshal string into Go struct field HostConfig.HostConfig.Mounts of type mount.Mount")
[2022-08-19 00:16:01,527] {taskinstance.py:1400} INFO - Marking task as UP_FOR_RETRY. dag_id=docker_dag, task_id=docker_command, execution_date=20220819T001554, start_date=20220819T001559, end_date=20220819T001601
[2022-08-19 00:16:01,565] {standard_task_runner.py:97} ERROR - Failed to execute job 586 for task docker_command (500 Server Error for http://docker-proxy:2375/v1.41/containers/create: Internal Server Error ("json: cannot unmarshal string into Go struct field HostConfig.HostConfig.Mounts of type mount.Mount"); 501)
[2022-08-19 00:16:01,616] {local_task_job.py:156} INFO - Task exited with return code 1
[2022-08-19 00:16:01,773] {local_task_job.py:273} INFO - 0 downstream tasks scheduled from follow-on schedule check
