[2022-10-27 00:52:55,591] {taskinstance.py:1159} INFO - Dependencies all met for <TaskInstance: example_kubernetes_executor.test_volume_mount manual__2022-10-27T00:52:52.053830+00:00 [queued]>
[2022-10-27 00:52:55,603] {taskinstance.py:1159} INFO - Dependencies all met for <TaskInstance: example_kubernetes_executor.test_volume_mount manual__2022-10-27T00:52:52.053830+00:00 [queued]>
[2022-10-27 00:52:55,604] {taskinstance.py:1356} INFO - 
--------------------------------------------------------------------------------
[2022-10-27 00:52:55,605] {taskinstance.py:1357} INFO - Starting attempt 1 of 1
[2022-10-27 00:52:55,605] {taskinstance.py:1358} INFO - 
--------------------------------------------------------------------------------
[2022-10-27 00:52:55,619] {taskinstance.py:1377} INFO - Executing <Task(_PythonDecoratedOperator): test_volume_mount> on 2022-10-27 00:52:52.053830+00:00
[2022-10-27 00:52:55,624] {standard_task_runner.py:52} INFO - Started process 162 to run task
[2022-10-27 00:52:55,628] {standard_task_runner.py:79} INFO - Running: ['***', 'tasks', 'run', 'example_kubernetes_executor', 'test_volume_mount', 'manual__2022-10-27T00:52:52.053830+00:00', '--job-id', '4', '--raw', '--subdir', '/home/***/.local/lib/python3.7/site-packages/***/example_dags/example_kubernetes_executor.py', '--cfg-path', '/tmp/tmp484f7ej9', '--error-file', '/tmp/tmph9pchr6z']
[2022-10-27 00:52:55,629] {standard_task_runner.py:80} INFO - Job 4: Subtask test_volume_mount
[2022-10-27 00:52:55,690] {task_command.py:369} INFO - Running <TaskInstance: example_kubernetes_executor.test_volume_mount manual__2022-10-27T00:52:52.053830+00:00 [running]> on host abbfe66d2e6a
[2022-10-27 00:52:55,776] {taskinstance.py:1571} INFO - Exporting the following env vars:
AIRFLOW_CTX_DAG_OWNER=***
AIRFLOW_CTX_DAG_ID=example_kubernetes_executor
AIRFLOW_CTX_TASK_ID=test_volume_mount
AIRFLOW_CTX_EXECUTION_DATE=2022-10-27T00:52:52.053830+00:00
AIRFLOW_CTX_TRY_NUMBER=1
AIRFLOW_CTX_DAG_RUN_ID=manual__2022-10-27T00:52:52.053830+00:00
[2022-10-27 00:52:55,779] {taskinstance.py:1889} ERROR - Task failed with exception
Traceback (most recent call last):
  File "/home/airflow/.local/lib/python3.7/site-packages/airflow/decorators/base.py", line 179, in execute
    return_value = super().execute(context)
  File "/home/airflow/.local/lib/python3.7/site-packages/airflow/operators/python.py", line 171, in execute
    return_value = self.execute_callable()
  File "/home/airflow/.local/lib/python3.7/site-packages/airflow/operators/python.py", line 189, in execute_callable
    return self.python_callable(*self.op_args, **self.op_kwargs)
  File "/home/airflow/.local/lib/python3.7/site-packages/airflow/example_dags/example_kubernetes_executor.py", line 91, in test_volume_mount
    with open('/foo/volume_mount_test.txt', 'w') as foo:
FileNotFoundError: [Errno 2] No such file or directory: '/foo/volume_mount_test.txt'
[2022-10-27 00:52:55,790] {taskinstance.py:1400} INFO - Marking task as FAILED. dag_id=example_kubernetes_executor, task_id=test_volume_mount, execution_date=20221027T005252, start_date=20221027T005255, end_date=20221027T005255
[2022-10-27 00:52:55,808] {standard_task_runner.py:97} ERROR - Failed to execute job 4 for task test_volume_mount ([Errno 2] No such file or directory: '/foo/volume_mount_test.txt'; 162)
[2022-10-27 00:52:55,842] {local_task_job.py:156} INFO - Task exited with return code 1
[2022-10-27 00:52:55,913] {local_task_job.py:273} INFO - 0 downstream tasks scheduled from follow-on schedule check
