[2022-08-04 01:13:27,658] {taskinstance.py:1159} INFO - Dependencies all met for <TaskInstance: trigger_rule_dag.task_2 scheduled__2022-08-03T00:00:00+00:00 [queued]>
[2022-08-04 01:13:27,682] {taskinstance.py:1159} INFO - Dependencies all met for <TaskInstance: trigger_rule_dag.task_2 scheduled__2022-08-03T00:00:00+00:00 [queued]>
[2022-08-04 01:13:27,683] {taskinstance.py:1356} INFO - 
--------------------------------------------------------------------------------
[2022-08-04 01:13:27,684] {taskinstance.py:1357} INFO - Starting attempt 1 of 1
[2022-08-04 01:13:27,685] {taskinstance.py:1358} INFO - 
--------------------------------------------------------------------------------
[2022-08-04 01:13:27,707] {taskinstance.py:1377} INFO - Executing <Task(BashOperator): task_2> on 2022-08-03 00:00:00+00:00
[2022-08-04 01:13:27,717] {standard_task_runner.py:52} INFO - Started process 52135 to run task
[2022-08-04 01:13:27,726] {standard_task_runner.py:79} INFO - Running: ['***', 'tasks', 'run', 'trigger_rule_dag', 'task_2', 'scheduled__2022-08-03T00:00:00+00:00', '--job-id', '298', '--raw', '--subdir', 'DAGS_FOLDER/trigger_rule_dag.py', '--cfg-path', '/tmp/tmpuli7iwci', '--error-file', '/tmp/tmpbl6c50rr']
[2022-08-04 01:13:27,728] {standard_task_runner.py:80} INFO - Job 298: Subtask task_2
[2022-08-04 01:13:27,947] {task_command.py:369} INFO - Running <TaskInstance: trigger_rule_dag.task_2 scheduled__2022-08-03T00:00:00+00:00 [running]> on host 2525a2c6e2b8
[2022-08-04 01:13:28,099] {taskinstance.py:1571} INFO - Exporting the following env vars:
AIRFLOW_CTX_DAG_OWNER=***
AIRFLOW_CTX_DAG_ID=trigger_rule_dag
AIRFLOW_CTX_TASK_ID=task_2
AIRFLOW_CTX_EXECUTION_DATE=2022-08-03T00:00:00+00:00
AIRFLOW_CTX_TRY_NUMBER=1
AIRFLOW_CTX_DAG_RUN_ID=scheduled__2022-08-03T00:00:00+00:00
[2022-08-04 01:13:28,101] {subprocess.py:62} INFO - Tmp dir root location: 
 /tmp
[2022-08-04 01:13:28,103] {subprocess.py:74} INFO - Running command: ['bash', '-c', 'exit 1']
[2022-08-04 01:13:28,120] {subprocess.py:85} INFO - Output:
[2022-08-04 01:13:28,122] {subprocess.py:96} INFO - Command exited with return code 1
[2022-08-04 01:13:28,142] {taskinstance.py:1889} ERROR - Task failed with exception
Traceback (most recent call last):
  File "/home/airflow/.local/lib/python3.7/site-packages/airflow/operators/bash.py", line 195, in execute
    f'Bash command failed. The command returned a non-zero exit code {result.exit_code}.'
airflow.exceptions.AirflowException: Bash command failed. The command returned a non-zero exit code 1.
[2022-08-04 01:13:28,147] {taskinstance.py:1400} INFO - Marking task as FAILED. dag_id=trigger_rule_dag, task_id=task_2, execution_date=20220803T000000, start_date=20220804T011327, end_date=20220804T011328
[2022-08-04 01:13:28,159] {standard_task_runner.py:97} ERROR - Failed to execute job 298 for task task_2 (Bash command failed. The command returned a non-zero exit code 1.; 52135)
[2022-08-04 01:13:28,200] {local_task_job.py:156} INFO - Task exited with return code 1
[2022-08-04 01:13:28,261] {local_task_job.py:273} INFO - 1 downstream tasks scheduled from follow-on schedule check
